Workbook

Sheet Download Test Cases
A1: TEST CASES - DOWNLOAD NHIỀU FILE
A2: Project: TCP File Downloader | D2: Total Test Cases | E2: 50 | H2: Overall Status | I2: Not Run
A3: Test Case ID | B3: Module / Screen | C3: Test Case / Description | D3: Input / Scenario | E3: Expected Output | F3: Actual Result 1 | G3: Actual Result 2 | H3: Status | I3: Proof | J3: Notes
A4: TC_D01 | B4: Client GUI | C4: Kết nối thành công | D4: Khởi động Client GUI và Server. Nhập đúng địa chỉ IP và Port mà Server đang lắng nghe, sau đó nhấn Connect. Theo dõi phản hồi của Client và Server. | E4: Client thiết lập được TCP connection với Server; Client không báo lỗi; giao diện chuyển sang trạng thái Connected; các chức năng cần kết nối Server như lấy danh sách file được phép sử dụng. | F4: Client kết nối thành công với Server bằng IP/Port hợp lệ. Giao diện chuyển sang trạng thái Connected, không phát sinh lỗi và các chức năng yêu cầu kết nối Server hoạt động bình thường. | H4: Pass | I4: =HYPERLINK("#'TC 01'!A1","TC 01") -> TC 01
A5: TC_D02 | B5: Client GUI | C5: Kết nối thất bại | D5: Khởi động Client khi Server không chạy hoặc nhập sai IP/Port. Nhấn Connect và chờ hết thời gian timeout nếu có. | E5: Client không thiết lập được kết nối; hiển thị thông báo lỗi/timeout phù hợp; GUI vẫn phản hồi; Khi Client trống (kết nối nhưng không tải gì) hiển thị thông báo đóng mất kết nối sau 5s, sau 25s không kết nối được với server thì hiển thị thông báo đóng Client hợp lệ. Nếu đang download giữa chừng Client sẽ dừng chờ Server, không tự động đóng Client | F5: Client hiển thị thông báo lỗi kết nối phù hợp, không bị crash và không chuyển sang trạng thái Connected giả. Khi không có hoạt động download, Client tự đóng sau khoảng 30 giây theo cơ chế hiện tại; khi đang download, Client dừng chờ Server và hiển thị lỗi thay vì tự đóng. | H5: Pass | I5: =HYPERLINK("#'TC 02'!A1","TC 02") -> TC 02
A6: TC_D03 | B6: Client GUI | C6: Hiển thị danh sách file từ Server | D6: Server có thư mục nguồn chứa tập file kiểm thử. Client kết nối thành công và thực hiện chức năng lấy danh sách file từ Server. | E6: Danh sách trên GUI chứa đầy đủ các file mà Server công bố trong thư mục nguồn; không tự ý thêm hoặc bỏ sót file; danh sách hiển thị ổn định sau khi nhận dữ liệu. | F6: Sau khi kết nối, Client nhận và hiển thị đầy đủ danh sách file do Server cung cấp từ thư mục nguồn; không ghi nhận file bị thiếu hoặc xuất hiện ngoài danh sách nguồn. | H6: Pass | I6: =HYPERLINK("#'TC 03'!A1","TC 03") -> TC 03
A7: TC_D04 | B7: Client GUI | C7: Chọn 1 file | D7: Client đã hiển thị danh sách. Người dùng click/chọn duy nhất một file trong danh sách. | E7: Chỉ file được chọn được đánh dấu selected; thông tin selection được cập nhật đúng; thao tác Add to Queue/Download chỉ tác động đến file đã chọn. | F7: File được chọn được đánh dấu selected chính xác. Các thao tác Add to Queue/Download chỉ tác động đến đúng file đã chọn. | H7: Pass | I7: =HYPERLINK("#'TC 04'!A1","TC 04") -> TC 04
A8: TC_D05 | B8: Client GUI | C8: Kéo thả hoặc chọn nhiều file | D8: Client có ít nhất 10 file. Người dùng chọn nhiều file bằng cơ chế kéo thả hoặc checkbox GUI hỗ trợ. | E8: Tất cả file được người dùng chọn đều ở trạng thái selected; không chọn nhầm file; số lượng selected nếu có counter phải khớp số thực tế. | F8: Client cho phép chọn nhiều file liền kề bằng thao tác kéo chọn hoặc chọn các file không liền kề bằng checkbox. Tất cả file được chọn đều được đánh dấu chính xác và các thao tác tiếp theo chỉ áp dụng cho nhóm file này. | H8: Pass | I8: =HYPERLINK("#'TC 05'!A1","TC 05") -> TC 05
A9: TC_D06 | B9: Client GUI | C9: Thử hủy một file trong quá trình tải | D9: Bấm hủy file khi file đang tải xuống | E9: Chỉ có file đó hiển thị Cancelled, các file khác vẫn tải bình thường | F9: Client hiện chưa hỗ trợ hủy riêng từng file đang download. Khi tải nhiều file và sử dụng chức năng Hủy trên thanh chức năng, toàn bộ file đều bị hủy chưa đáp ứng được kết quả mong muốn | G9: Tải toàn bộ file cùng một lúc, chọn Hủy trên thanh chức năng, hiển thị đúng 1 file bị hủy, các file khác không bị ảnh hưởng | H9: Pass | I9: =HYPERLINK("#'TC 06'!A1","TC 06") -> TC 06
A10: TC_D07 | B10: Client GUI | C10: Thử tải lại file đã hủy | D10: Bấm thử lại trên dòng Failed/Cancelled | E10: Chạy lại từ đầu, khi hoàn thành hiển thị đúng trạng thái hoàn thành | F10: File vừa bị hủy được thử lại thành công từ đầu. Sau khi download hoàn tất, file hiển thị đúng trạng thái thành công. | H10: Pass | I10: =HYPERLINK("#'TC 07'!A1","TC 07") -> TC 07
A11: TC_D08 | B11: Client GUI | C11: Chọn số lượng lớn | D11: Người dùng thực hiện chọn một số lượng lớn file, ví dụ 50, 100 hoặc toàn bộ file, bằng cơ chế GUI hỗ trợ. | E11: GUI ghi nhận đúng toàn bộ các file được chọn; không bỏ sót, chọn nhầm hoặc lag bất thường; thao tác selection hoàn tất mà ứng dụng vẫn phản hồi. | F11: Khi chọn khoảng 15–20 file bằng checkbox, Client ghi nhận đầy đủ các file được chọn, không chọn nhầm hoặc bỏ sót. Giao diện vẫn phản hồi bình thường trong suốt quá trình thao tác. | H11: Pass | I11: =HYPERLINK("#'TC 08'!A1","TC 08") -> TC 08
A12: TC_D09 | B12: Client GUI | C12: Select All | D12: Client đã nhận toàn bộ danh sách file. Người dùng nhấn Select All/checkbox tổng hoặc chức năng tương đương. | E12: Toàn bộ file đang hiển thị được chọn; số lượng selected bằng tổng số file hợp lệ; trạng thái selection đồng nhất; có thể đưa toàn bộ danh sách vào Queue theo chức năng tiếp theo. | F12: Sau khi sử dụng Select All hoặc chọn toàn bộ bằng checkbox, toàn bộ file trong danh sách được đánh dấu selected và trạng thái lựa chọn được hiển thị đồng nhất. | H12: Pass | I12: =HYPERLINK("#'TC 09'!A1","TC 09") -> TC 09
A13: TC_D10 | B13: Client GUI | C13: GUI không treo khi đang tải một lúc nhiều file | D13: Trong lúc danh sách được tải và sau khi hiển thị, người dùng thực hiện các thao tác tùy ý và chuyển qua lại các khu vực GUI. | E13: GUI vẫn phản hồi thao tác người dùng; cửa sổ không rơi vào Not Responding; danh sách không bị mất dòng/hiển thị sai; không crash và không làm gián đoạn kết nối. | F13: Trong khi nhiều file đang được tải, GUI vẫn phản hồi thao tác người dùng, không chuyển sang trạng thái Not Responding; danh sách không bị mất dòng và quá trình download không bị gián đoạn. | H13: Pass | I13: =HYPERLINK("#'TC 10'!A1","TC 10") -> TC 10
A14: TC_D11 | B14: Download Queue | C14: Thêm 1 file | D14: Client đã kết nối và có ít nhất một file hợp lệ. Người dùng chọn đúng 1 file rồi nhấn Add to Queue/Download. | E14: Đúng 1 file được thêm vào Download Queue; thông tin tên/dung lượng khớp file đã chọn; file mới ở trạng thái Waiting nếu chưa bắt đầu download. | F14: Một file được chọn và thêm vào Download Queue thành công. Tên, dung lượng hiển thị trong Queue khớp với file nguồn và trạng thái ban đầu là Waiting. | H14: Pass | I14: =HYPERLINK("#'TC 11'!A1","TC 11") -> TC 11
A15: TC_D12 | B15: Download Queue | C15: Thêm nhiều file | D15: Client có nhiều file. Người dùng chọn từ 5 đến 10 file rồi thực hiện Add to Queue. | E15: Tất cả file đã chọn xuất hiện trong Queue đúng một lần; metadata từng dòng đúng; trạng thái ban đầu là Waiting nếu chưa download. | F15: Năm file được chọn và thêm vào Download Queue trong một lần thao tác. Cả 5 file xuất hiện đúng một lần, thông tin tên/dung lượng khớp file nguồn và trạng thái ban đầu là Waiting. | H15: Pass | I15: =HYPERLINK("#'TC 12'!A1","TC 12") -> TC 12
A16: TC_D13 | B16: Download Queue | C16: Thêm toàn bộ file | D16: Client hiển thị khoảng 147 file. Người dùng Select All rồi thực hiện Add to Queue/Download All theo chức năng của ứng dụng. | E16: Toàn bộ khoảng 147 file được đưa vào Queue đúng một lần; không file nào bị bỏ sót; Queue vẫn phản hồi và GUI không crash khi xử lý số lượng lớn. | F16: Toàn bộ file được chọn và đưa vào Download Queue trong một lần thao tác. Các item trong Queue hiển thị đúng thông tin file và trạng thái chờ; không ghi nhận file bị bỏ sót. | H16: Pass | I16: =HYPERLINK("#'TC 13'!A1","TC 13") -> TC 13
A17: TC_D14 | B17: Download Queue | C17: Không thêm trùng | D17: Thêm một file vào Queue. Sau đó chọn lại chính file đó và thực hiện Add to Queue thêm lần nữa; lặp lại nếu cần. | E17: Queue không tạo thêm item trùng cho cùng một file theo định danh mà ứng dụng quy định; nếu hệ thống có thông báo duplicate thì thông báo rõ ràng; các item khác không bị ảnh hưởng. | F17: Khi chọn lại một file đã có trong Queue, Client không tạo thêm item trùng. Queue vẫn giữ nguyên item ban đầu. | H17: Pass | I17: =HYPERLINK("#'TC 14'!A1","TC 14") -> TC 14
A18: TC_D15 | B18: Download Queue | C18: Hiển thị Waiting | D18: Thêm nhiều file vào Queue nhưng chưa bắt đầu download hoặc khi số lượng file vượt số slot download đồng thời. | E18: Mỗi file chưa được xử lý phải hiển thị trạng thái Waiting; trạng thái không bị hiển thị thành Downloading/Completed khi chưa thực sự xảy ra; số lượng Waiting phản ánh đúng Queue. | F18: Các file mới thêm vào Queue đều hiển thị đúng trạng thái Waiting; không xuất hiện trạng thái Downloading hoặc Completed trước khi file được xử lý. | H18: Pass | I18: =HYPERLINK("#'TC 15'!A1","TC 15") -> TC 15
A19: TC_D16 | B19: Download Queue | C19: Download 1 file | D19: Queue chứa đúng 1 file hợp lệ. Client đã Connected. Người dùng bắt đầu download file. | E19: File chuyển từ Waiting sang Downloading, nhận dữ liệu và sau khi nhận đủ chuyển sang Completed; file lưu thành công tại thư mục đích; progress đạt 100% và không báo lỗi. | F19: File được chọn chuyển sang trạng thái Downloading trong quá trình truyền. Sau khi hoàn tất, progress đạt 100% và file được lưu tại thư mục Download. | H19: Pass | I19: =HYPERLINK("#'TC 16'!A1","TC 16") -> TC 16
A20: TC_D17 | B20: Download Queue | C20: Download nhiều file | D20: Queue chứa ít nhất 5 file hợp lệ. Client đã Connected và người dùng thực hiện Download All. | E20: Tất cả file được đưa vào quy trình download; các file có thể chạy đồng thời theo giới hạn 3 file 1 lần theo thiết kế; từng file có trạng thái, progress và kết quả riêng; không file nào bị bỏ sót. | F20: Bảy file được chọn nhưng Client không xử lý download đồng thời theo cách kiểm thử mong muốn; các file được xử lý theo cơ chế tuần tự của ứng dụng. Kết quả không đáp ứng tiêu chí kiểm thử về download nhiều file đồng thời. | G20: Bảy file được chọn xử lý download đồng thời với giới hạn 3 file 1 lần theo thiết kế, không Crash, không treo GUI | H20: Pass | I20: =HYPERLINK("#'TC 17'!A1","TC 17") -> TC 17
A21: TC_D18 | B21: Download Queue | C21: Download toàn bộ file | D21: Server hoạt động ổn định, Client đã Connected. Người dùng thực hiện Download All. | E21: Toàn bộ khoảng file được đưa vào xử lý; các file lần lượt sử dụng slot download theo giới hạn thiết kế; cuối phiên mỗi file phải có kết quả rõ ràng, không mất item, không crash và không treo GUI. | F21: Khi chọn toàn bộ file trong Queue, Client không xử lý tất cả file đồng thời theo tiêu chí kiểm thử mà thực hiện theo cơ chế xử lý của ứng dụng. Kết quả không đáp ứng tiêu chí kiểm thử về xử lý đồng thời toàn bộ file. | G21: Toàn bộ file được đưa vào xử lý với giới hạn 3 file 1 lần theo đúng thiết kế, cuối phiên có kết quả rõ ràng, không treo GUI, không Crash | H21: Pass | I21: =HYPERLINK("#'TC 18'!A1","TC 18") -> TC 18
A22: TC_D19 | B22: Download Queue | C22: Progress + Speed | D22: Bắt đầu download một hoặc nhiều file đủ lớn để quá trình truyền diễn ra trong thời gian quan sát được. | E22: Mỗi file đang Downloading hiển thị progress tăng theo dữ liệu đã nhận và speed được cập nhật theo thời gian; progress không giảm bất thường, không vượt 100%; khi hoàn tất progress đạt 100%. | F22: Trong khi download, thanh tiến độ tăng ổn định theo lượng dữ liệu nhận được. Tốc độ được hiển thị theo đơn vị MB/s và cập nhật trong quá trình truyền; khi hoàn tất, progress đạt 100%. | H22: Pass | I22: =HYPERLINK("#'TC 19'!A1","TC 19") -> TC 19
A23: TC_D20 | B23: Server | C23: Server khởi động | D23: Chạy chương trình Server với cấu hình IP/Port và thư mục nguồn hợp lệ. | E23: Server khởi động thành công, bind/listen đúng IP/Port, không crash; sẵn sàng nhận kết nối từ Client và có thể phục vụ yêu cầu danh sách/download. | F23: Server khởi động thành công sau khi chọn thư mục nguồn và nhấn Start Server. Status hiển thị “Server Online - Port 5000”; Server không crash và chuyển sang trạng thái sẵn sàng nhận kết nối từ Client. | H23: Pass | I23: =HYPERLINK("#'TC 20'!A1","TC 20") -> TC 20
A24: TC_D21 | B24: Server | C24: Server đọc file trực tiếp từ ổ cứng | D24: Đặt file thật trong thư mục nguồn trên ổ cứng Server. Không đưa dữ liệu file vào danh sách hard-code. Thêm/sửa file trực tiếp trong thư mục nguồn rồi yêu cầu Client lấy danh sách. | E24: Server đọc metadata và dữ liệu trực tiếp từ filesystem tại thời điểm xử lý; file mới xuất hiện được phản ánh theo cơ chế thiết kế; nội dung download lấy từ file thực tế trên ổ cứng, không phải dữ liệu giả/hard-code. | F24: Trong khi Server đang chạy, thêm file mới vào thư mục nguồn rồi chọn Làm mới. Danh sách cập nhật từ 20 lên 21 file và log ghi nhận “Đã cập nhật danh sách: 21 file”, xác nhận Server đọc dữ liệu trực tiếp từ filesystem. | H24: Pass | I24: =HYPERLINK("#'TC 21'!A1","TC 21") -> TC 21
A25: TC_D22 | B25: Server | C25: Danh sách file chính xác | D25: Thư mục nguồn chứa tập file kiểm thử với tên, extension và dung lượng đã biết. Client gửi request lấy danh sách. | E25: Server trả về đúng danh sách file hợp lệ trong thư mục nguồn và metadata tương ứng; số lượng, tên và dung lượng khớp filesystem. | F25: Đối chiếu 21 file Server trả về với dữ liệu thực tế trong thư mục TestCaseLapTrinhMang cho thấy tên, đường dẫn và dung lượng của các file khớp với filesystem. | H25: Pass | I25: =HYPERLINK("#'TC 22'!A1","TC 22") -> TC 22
A26: TC_D23 | B26: Server | C26: Không lấy file ngoài thư mục nguồn | D26: Tạo thư mục nguồn và một hoặc nhiều file ở ngoài thư mục nguồn. Client yêu cầu danh sách file. | E26: Chỉ các file thuộc phạm vi thư mục nguồn được trả về; file ở thư mục cha, thư mục khác hoặc vị trí ngoài source directory không xuất hiện trong danh sách và không được download thông qua cơ chế bình thường. | F26: Khi đặt một file bên ngoài thư mục nguồn và làm mới danh sách nhiều lần, số lượng file vẫn giữ ở 21; file nằm ngoài source directory không xuất hiện. | H26: Pass | I26: =HYPERLINK("#'TC 23'!A1","TC 23") -> TC 23
A27: TC_D24 | B27: Server | C27: Download file tồn tại | D27: Client request download một file đang tồn tại trong thư mục nguồn và có quyền đọc. | E27: Server xác thực file hợp lệ, mở đúng file trên disk và truyền đầy đủ dữ liệu cho Client; không gửi nhầm file; Server vẫn tiếp tục phục vụ request khác. | F27: Ba file được thêm vào Queue và download thành công. File Orange3-3.40.0-x86_64.exe đạt 59% trong quá trình tải và Server Log xác nhận đã gửi đủ 387,02 MB đến đúng Client. Server tiếp tục hoạt động bình thường sau request. | H27: Pass | I27: =HYPERLINK("#'TC 24'!A1","TC 24") -> TC 24
A28: TC_D25 | B28: Server | C28: Xử lý file không tồn tại | D28: Client gửi request tới một file đã bị xóa/đổi tên sau khi danh sách được lấy hoặc request chứa tên file không tồn tại. | E28: Server không crash; trả về lỗi/trạng thái phù hợp cho Client; không tạo file dữ liệu rỗng giả như thể download thành công; connection/request được xử lý sạch. | F28: Sau khi file Big_C__2nd_edition.pdf bị xóa khỏi thư mục nguồn nhưng vẫn còn trong Queue, Client không hiển thị trạng thái Failed/Error mà dòng file tự biến mất khỏi danh sách. Các file khác vẫn download bình thường; kết quả chưa đáp ứng yêu cầu về thông báo lỗi rõ ràng. | G28: Sau khi file "Honkai_ Star Rail 2026-06-11 09-10-06" bị xóa khỏi thư mục nguồn nhưng còn tồn tại trong Queue, Client khi tải trả lỗi hợp lệ về file này, các file khác không bị ảnh hưởng, không treo GUI, không Crash | H28: Pass | I28: =HYPERLINK("#'TC 25'!A1","TC 25") -> TC 25
A29: TC_D26 | B29: Server | C29: Đóng Server có trình tự | D29: Đóng/Ngắt kết nối Server khi đang có 2-3 Client đang kết nối nhưng không download (Client trống) | E29: Đóng lần lượt các client, thông báo đóng Client sau 25s, không kill cứng các client | H29: Not Run | I29: =HYPERLINK("#'TC 26'!A1","TC 26") -> TC 26
A30: TC_D27 | B30: Server | C30: Truyền file nhiều chunk | D30: Chọn file có kích thước lớn hơn kích thước buffer/chunk của protocol. Client thực hiện download. | E30: Server chia dữ liệu thành nhiều chunk/packet theo protocol; Client nhận đủ và ghép đúng thứ tự; không mất, trùng hoặc đảo dữ liệu; Server không giữ toàn bộ file trong memory nếu thiết kế yêu cầu streaming. | F30: File pycharm-2026.1.2.exe dung lượng 865,2 MB được truyền qua nhiều lần đọc/ghi buffer 8192 byte. Progress tăng dần đến 100%, dung lượng file nhận được khớp file nguồn và không ghi nhận mất hoặc trùng dữ liệu. | H30: Pass | I30: =HYPERLINK("#'TC 27'!A1","TC 27") -> TC 27
A31: TC_D28 | B31: Server | C31: Nhiều Client download đồng thời | D31: Khởi chạy từ 2 Client trở lên và cho các Client đồng thời yêu cầu download các file khác nhau hoặc cùng một file. | E31: Server phục vụ đồng thời các Client theo thiết kế; mỗi connection nhận đúng dữ liệu của request; một Client chậm/lỗi không làm crash hoặc làm sai dữ liệu của Client khác. | F31: Hai Client cùng kết nối tới Server và download hai file khác nhau đồng thời. Mỗi Client nhận đúng file tương ứng, progress hoạt động độc lập, không Client nào bị treo và Server tiếp tục phục vụ ổn định cả hai kết nối. | H31: Pass | I31: =HYPERLINK("#'TC 28'!A1","TC 28") -> TC 28
A32: TC_D29 | B32: Server | C32: Server xử lý số lượng request/file lớn | D32: Từ một hoặc nhiều Client gửi liên tiếp nhiều request, tổng cộng khoảng 100–147 file hoặc số lượng lớn phù hợp tài nguyên máy. | E32: Server xử lý hết request hợp lệ hoặc trả lỗi có kiểm soát khi vượt giới hạn; không crash, deadlock hoặc rò rỉ tài nguyên nghiêm trọng; không trả nhầm file và vẫn có khả năng phục vụ Client. | F32: Một Client đưa 19 file, tổng dung lượng khoảng 2851,6 MB, vào Queue và thực hiện download. Cả 19 file đạt 100% với thông báo “Thành công: 19 | Lỗi: 0”. Server không crash hoặc treo trong suốt quá trình. | H32: Pass | I32: =HYPERLINK("#'TC 29'!A1","TC 29") -> TC 29
A33: TC_D30 | B33: Network | C33: Connect thành công | D33: Client nhập đúng IP/Port của Server đang listen và gửi yêu cầu kết nối qua mạng. | E33: TCP connection được thiết lập thành công; Client nhận phản hồi handshake/protocol nếu có; trạng thái Connected hiển thị đúng và có thể tiếp tục request file. | F33: Client kết nối thành công bằng IP 127.0.0.1 và Port 5000. Server Log ghi nhận connection từ Client; Client lấy được danh sách file và tiếp tục thực hiện download bình thường. | H33: Pass | I33: =HYPERLINK("#'TC 30'!A1","TC 30") -> TC 30
A34: TC_D31 | B34: Network | C34: Connect sai IP/Port | D34: Nhập IP không tồn tại hoặc Port không có Server listen. Thực hiện Connect. | E34: Connection thất bại hoặc timeout theo thiết kế; Client hiển thị lỗi rõ ràng; không bị treo vô thời hạn, không crash và không đánh dấu Connected. | F34: Khi sử dụng Port 9999 không có Server lắng nghe, Client hiển thị thông báo “Kết nối thất bại” kèm nguyên nhân connection refused sau khoảng 4–5 giây. Client không treo, không crash và không hiển thị Connected giả. | H34: Pass | I34: =HYPERLINK("#'TC 31'!A1","TC 31") -> TC 31
A35: TC_D32 | B35: Network | C35: Mất kết nối khi download | D35: Bắt đầu download file lớn rồi chủ động làm gián đoạn đường truyền giữa Client và Server. | E35: Client phát hiện connection failure/timeout; file hiện tại chuyển Failed/Error hoặc trạng thái tương ứng; progress không tiếp tục giả; GUI vẫn hoạt động và các tài nguyên liên quan được giải phóng. | H35: Not Run | I35: =HYPERLINK("#'TC 32'!A1","TC 32") -> TC 32 | J35: Không thực hiện được đúng kịch bản vì môi trường test hiện tại là localhost (127.0.0.1), không có đường truyền mạng vật lý để chủ động ngắt giữa chừng.
A36: TC_D33 | B36: Network | C36: Server tắt giữa quá trình download | D36: Client đang download file lớn. Tắt Server trước khi file hoàn tất. | E36: Client nhận biết Server không còn phản hồi; download đang chạy chuyển sang Failed/Error/Disconnected theo thiết kế; Client không crash; không đánh dấu file Completed khi chưa nhận đủ dữ liệu. | F36: Trong khi file đang download, Server được dừng. Client phát hiện mất kết nối và hiển thị thông báo “Mất kết nối - Mất kết nối tới Server (Server có thể đã dừng)”. File chưa nhận đủ dữ liệu không được báo Completed. | H36: Pass | I36: =HYPERLINK("#'TC 33'!A1","TC 33") -> TC 33
A37: TC_D34 | B37: Network | C37: Client ngắt giữa chừng | D37: Đang download một hoặc nhiều file. Đóng Client hoặc chủ động đóng connection giữa chừng. | E37: Client dừng hoạt động của request đang chạy và giải phóng tài nguyên; Server xử lý disconnect của Client mà không crash; các Client/request khác vẫn hoạt động. | F37: Khi Client bị đóng đột ngột giữa quá trình download, Server Log ghi nhận lỗi transport connection và sau đó ghi nhận Client ngắt kết nối. Server không crash và vẫn tiếp tục phục vụ các connection khác. | H37: Pass | I37: =HYPERLINK("#'TC 34'!A1","TC 34") -> TC 34
A38: TC_D35 | B38: Network | C38: Một kết nối lỗi không ảnh hưởng kết nối khác | D38: Có ít nhất 2 Client cùng download. Làm một Client mất kết nối trong khi Client còn lại vẫn download bình thường. | E38: Chỉ connection bị lỗi chuyển trạng thái lỗi; Client còn lại tiếp tục nhận đúng dữ liệu và hoàn tất download; Server không dừng toàn bộ dịch vụ. | F38: Khi Client 1 bị đóng giữa quá trình download, Client 2 vẫn tiếp tục tải SEB_3.10.1.864_SetupBundle.exe và hoàn tất thành công với thông báo “Thành công: 1 | Lỗi: 0”. Server không bị dừng và tiếp tục phục vụ Client 2. | H38: Pass | I38: =HYPERLINK("#'TC 35'!A1","TC 35") -> TC 35
A39: TC_D36 | B39: Network | C39: Reconnect sau khi Server hoạt động lại | D39: Client đang ở trạng thái mất kết nối. Server được khởi động lại với IP/Port đúng. Client thực hiện Connect lại. | E39: Client thiết lập được connection mới sau khi Server listen trở lại; trạng thái chuyển Connected; có thể lấy lại danh sách file và download file mới thành công. | F39: Sau khi Server được dừng, Client báo không thể kết nối. Khi Server khởi động lại với cùng IP/Port, Client kết nối lại thành công, xác nhận Server phản hồi bình thường và tải lại danh sách 19 file mà không cần khởi động lại Client. | H39: Pass | I39: =HYPERLINK("#'TC 36'!A1","TC 36") -> TC 36
A40: TC_D37 | B40: Network | C40: Download file lớn qua mạng | D40: Chọn file lớn và thực hiện download qua kết nối mạng thực tế của project. | E40: Dữ liệu được truyền đầy đủ qua nhiều packet/chunk; thời gian download có thể dài nhưng Client không treo; file kết quả có kích thước và nội dung đúng với file nguồn. | F40: File pycharm-2026.1.2.exe dung lượng 865,2 MB được download qua 127.0.0.1:5000. Client vẫn phản hồi trong suốt quá trình truyền, progress đạt 100% và dung lượng file nhận được khớp với file nguồn. | H40: Pass | I40: =HYPERLINK("#'TC 37'!A1","TC 37") -> TC 37
...

Sheet Summary
A1: DOWNLOAD TEST SUMMARY
A3: Tổng số TC | B3: 43 | D3: Cấu trúc | E3: 10 + 10 + 10 + 10 + 4 = 43 TC
A4: Pass | B4: =COUNTIF('Download Test Cases'!H:H,"Pass") -> 37 | D4: Input / Scenario | E4: Điều kiện, dữ liệu và thao tác cần thực hiện
A5: Fail | B5: =COUNTIF('Download Test Cases'!H:H,"Fail") -> 0 | D5: Expected Output | E5: Kết quả hệ thống bắt buộc phải đạt
A6: Blocked | B6: =COUNTIF('Download Test Cases'!H:H,"Blocked") -> 0 | D6: Actual Result | E6: Người test ghi kết quả thực tế quan sát được
A7: Not Run | B7: =COUNTIF('Download Test Cases'!H:H,"Not Run") -> 2 | D7: Status | E7: Chọn Not Run / Pass / Fail / Blocked / N/A
A8: N/A | B8: =COUNTIF('Download Test Cases'!H:H,"N/A") -> 0

Sheet TC 01
B2: TC 01
B3: Hình ảnh minh chứng tại đây.

Sheet TC 02
B2: TC 02
B3: Hình ảnh minh chứng tại đây.
B4: Thông báo mất kết nối sau 5s
B62: Thông báo đóng Client sau 25s không kết nối được với Server
B103: Thông báo lỗi khi đang tải giữa chừng

Sheet TC 03
B2: TC 03

Sheet TC 04
B2: TC 04

Sheet TC 05
B2: TC 05
B4: Checkbox
B45: Kéo thả file liền kề

Sheet TC 06
B2: TC 06

Sheet TC 07
B2: TC 07

Sheet TC 08
B3: TC 08

Sheet TC 09
B2: TC 09
B4: Kéo thả
B45: Checkbox

Sheet TC 10
B2: TC 10

Sheet TC 11
B2: TC 11

Sheet TC 12
B2: TC 12

Sheet TC 13
B2: TC 13

Sheet TC 14
B2: TC 14

Sheet TC 15
B2: TC 15

Sheet TC 16
B2: TC 16

Sheet TC 17
B2: TC 17

Sheet TC 18
B2: TC 18

Sheet TC 19
B2: TC 19

Sheet TC 20
B2: TC 20
B3: Hình ảnh minh chứng tại đây

Sheet TC 21

Sheet TC 22

Sheet TC 23

Sheet TC 24

Sheet TC 25
B2: TC 25

Sheet TC 26

Sheet TC 27

Sheet TC 28

Sheet TC 29

Sheet TC 30

Sheet TC 31

Sheet TC 32

Sheet TC 33

Sheet TC 34

Sheet TC 35

Sheet TC 36

Sheet TC 37

Sheet TC 38

Sheet TC 39

Sheet TC 40

Sheet TC 41

Sheet TC 42

Sheet TC 43
